Workbook

Sheet README
B1: AI Academy + AI Tools + AI Film Studio — Financial Model / Business Case
B3: PURPOSE — a working model of the OPC business: the course ladder, recurring AI-tool revenue, and the AI Film Studio.
B4: Prepared 2026-07-28. Currency: MYR (RM). All figures ILLUSTRATIVE — edit the Assumptions tab and everything recomputes.
B6: HOW TO USE
B7: 1) Open the 'Assumptions' tab. Cells in BLUE are inputs you can change; YELLOW cells are the scenario levers.
B8: 2) The 'P&L (Year 1)' tab builds three scenarios (Conservative / Base / Aggressive) from those inputs.
B9: 3) The 'Unit Economics' tab shows value per intro buyer, LTV:CAC and break-even — the core decision metrics.
B11: COLOUR KEY: blue = input · black = formula · green = link to another sheet · yellow = scenario lever.
B13: KEY ASSUMPTIONS & SOURCES
B14: • Pricing = our agreed ladder (Bootcamp RM3,999 / Certificate RM18k / Diploma RM32k / Mastery RM48k; intro RM299).
B15: • Conversion rates = our target ladder economics (intro→bootcamp 25%, bootcamp→cert 20%, cert→dip 35%, dip→mastery 35%).
B16: • Market benchmark (MY/SG 2026) informs pricing: MY workshops RM2–8k, diplomas RM15–30k, bachelor ~RM76.8k;
... B23: CAVEAT: Volumes, conversion and cost inputs are planning estimates, not commitments. Replace with real cohort data after Q3 pilots.

Sheet Assumptions
A1: ASSUMPTIONS (blue = input · yellow = scenario lever)
A3: PRICING (RM)
A4: Intro / Discovery price | B4: 299
A5: Bootcamp — Professionals (S2) | B5: 3999
A6: Bootcamp — Graduates (S1) | B6: 1799
A7: Bootcamp — % Professionals (S2) | B7: 0.55
A8: Certificate — Professionals (S2) | B8: 18000
A9: Certificate — Graduates (S1) | B9: 12000
A10: Certificate — % Professionals (S2) | B10: 0.45
A11: Diploma (2 yr) | B11: 32000
A12: Mastery / Founder Track (4 yr) | B12: 48000
A13: Tool plan — Cora AI Gateway (RM/mo) | B13: 99
A14: LADDER CONVERSION (base rates)
A15: Intro → Bootcamp | B15: 0.25
A16: Bootcamp → Certificate | B16: 0.2
A17: Certificate → Diploma | B17: 0.35
A18: Diploma → Mastery | B18: 0.35
A19: TOOLS & FILM
A20: Tool avg paying months (Year 1) | B20: 6
A21: Tool lifetime months (for LTV) | B21: 18
A22: Tool gross margin | B22: 0.7
A23: (row 23 intentionally blank)
A24: Avg film price (DFY) | B24: 50000
A25: Film gross margin (AI, ~80% cheaper) | B25: 0.7
A26: COSTS
A27: Course delivery COGS (% of course rev) | B27: 0.35
A28: Brand / content marketing (fixed, /yr) | B28: 100000
A29: Team salaries (/yr) | B29: 720000
A30: Software / LMS / CRM / payments (/yr) | B30: 120000
A31: Legal / compliance (film + ISA, /yr) | B31: 80000
A32: G&A / misc (/yr) | B32: 100000
A33: YEAR-1 REVENUE RECOGNITION (share delivered in Year 1)
A34: Intro | B34: 1
A35: Bootcamp | B35: 1
A36: Certificate | B36: 0.5
A37: Diploma | B37: 0.25
A38: Mastery | B38: 0.125
D40: SCENARIO LEVERS | E40: Conservative | F40: Base | G40: Aggressive
D41: Intro buyers (Year 1) | E41: 1000 | F41: 2000 | G41: 4000
D42: Conversion multiplier | E42: 0.7 | F42: 1 | G42: 1.2
...

Sheet P&L (Year 1)
A1: P&L — YEAR 1 (recognised basis, RM)
A3: Line item (RM) | B3: Conservative | C3: Base | D3: Aggressive
A4: Volumes
A5: Intro buyers | B5: =Assumptions!E41 | C5: =Assumptions!F41 | D5: =Assumptions!G41
A6: Bootcamp students | B6: =B5*Assumptions!$B$15*Assumptions!E42 | C6: =C5*Assumptions!$B$15*Assumptions!F42 | D6: =D5*Assumptions!$B$15*Assumptions!G42
A7: Certificate students | B7: =B6*Assumptions!$B$16*Assumptions!E42 | C7: =C6*Assumptions!$B$16*Assumptions!F42 | D7: =D6*Assumptions!$B$16*Assumptions!G42
A8: Diploma students | B8: =B7*Assumptions!$B$17*Assumptions!E42 | C8: =C7*Assumptions!$B$17*Assumptions!F42 | D8: =D7*Assumptions!$B$17*Assumptions!G42
A9: Mastery students | B9: =B8*Assumptions!$B$18*Assumptions!E42 | C9: =C8*Assumptions!$B$18*Assumptions!F42 | D9: =D8*Assumptions!$B$18*Assumptions!G42
A11: Revenue — recognised
A12: Intro | B12: =B5*Assumptions!$B$4*Assumptions!$B$34 | C12: =C5*Assumptions!$B$4*Assumptions!$B$34 | D12: =D5*Assumptions!$B$4*Assumptions!$B$34
A13: Bootcamp | B13: =B6*(Assumptions!$B$5*Assumptions!$B$7+Assumptions!$B$6*(1-Assumptions!$B$7))*Assumptions!$B$35 | C13: =C6*(Assumptions!$B$5*Assumptions!$B$7+Assumptions!$B$6*(1-Assumptions!$B$7))*Assumptions!$B$35 | D13: =D6*(Assumptions!$B$5*Assumptions!$B$7+Assumptions!$B$6*(1-Assumptions!$B$7))*Assumptions!$B$35
A14: Certificate | B14: =B7*(Assumptions!$B$8*Assumptions!$B$10+Assumptions!$B$9*(1-Assumptions!$B$10))*Assumptions!$B$36 | C14: =C7*(Assumptions!$B$8*Assumptions!$B$10+Assumptions!$B$9*(1-Assumptions!$B$10))*Assumptions!$B$36 | D14: =D7*(Assumptions!$B$8*Assumptions!$B$10+Assumptions!$B$9*(1-Assumptions!$B$10))*Assumptions!$B$36
A15: Diploma | B15: =B8*Assumptions!$B$11*Assumptions!$B$37 | C15: =C8*Assumptions!$B$11*Assumptions!$B$37 | D15: =D8*Assumptions!$B$11*Assumptions!$B$37
A16: Mastery | B16: =B9*Assumptions!$B$12*Assumptions!$B$38 | C16: =C9*Assumptions!$B$12*Assumptions!$B$38 | D16: =D9*Assumptions!$B$12*Assumptions!$B$38
A17: Course revenue | B17: =SUM(B12:B16) | C17: =SUM(C12:C16) | D17: =SUM(D12:D16)
A18: Tool revenue (recurring) | B18: =B6*Assumptions!E44*Assumptions!$B$20*Assumptions!$B$13 | C18: =C6*Assumptions!F44*Assumptions!$B$20*Assumptions!$B$13 | D18: =D6*Assumptions!G44*Assumptions!$B$20*Assumptions!$B$13
A19: Film revenue (DFY) | B19: =Assumptions!E43*Assumptions!$B$24 | C19: =Assumptions!F43*Assumptions!$B$24 | D19: =Assumptions!G43*Assumptions!$B$24
A20: TOTAL REVENUE | B20: =B17+B18+B19 | C20: =C17+C18+C19 | D20: =D17+D18+D19
A22: Cost of delivery (COGS)
A23: Course COGS | B23: =B17*Assumptions!$B$27 | C23: =C17*Assumptions!$B$27 | D23: =D17*Assumptions!$B$27
A24: Tool COGS | B24: =B18*(1-Assumptions!$B$22) | C24: =C18*(1-Assumptions!$B$22) | D24: =D18*(1-Assumptions!$B$22)
A25: Film COGS | B25: =B19*(1-Assumptions!$B$25) | C25: =C19*(1-Assumptions!$B$25) | D25: =D19*(1-Assumptions!$B$25)
A26: Total COGS | B26: =SUM(B23:B25) | C26: =SUM(C23:C25) | D26: =SUM(D23:D25)
A27: GROSS PROFIT | B27: =B20-B26 | C27: =C20-C26 | D27: =D20-D26
A28: Gross margin % | B28: =B27/B20 | C28: =C27/C20 | D28: =D27/D20
A30: Operating expenses
A31: Marketing (CAC × intro + brand) | B31: =B5*Assumptions!E45+Assumptions!$B$28 | C31: =C5*Assumptions!F45+Assumptions!$B$28 | D31: =D5*Assumptions!G45+Assumptions!$B$28
A32: Team salaries | B32: =Assumptions!$B$29 | C32: =Assumptions!$B$29 | D32: =Assumptions!$B$29
A33: Software / platform | B33: =Assumptions!$B$30 | C33: =Assumptions!$B$30 | D33: =Assumptions!$B$30
A34: Legal / compliance | B34: =Assumptions!$B$31 | C34: =Assumptions!$B$31 | D34: =Assumptions!$B$31
A35: G&A / misc | B35: =Assumptions!$B$32 | C35: =Assumptions!$B$32 | D35: =Assumptions!$B$32
A36: Total OpEx | B36: =SUM(B31:B35) | C36: =SUM(C31:C35) | D36: =SUM(D31:D35)
A38: EBITDA | B38: =B27-B36 | C38: =C27-C36 | D38: =D27-D36
A39: EBITDA margin % | B39: =B38/B20 | C39: =C38/C20 | D39: =D38/D20
A41: MEMO
A42: Course bookings (full contract value) | B42: =B5*Assumptions!$B$4+B6*(Assumptions!$B$5*Assumptions!$B$7+Assumptions!$B$6*(1-Assumptions!$B$7))+B7*(Assumptions!$B$8*Assumptions!$B$10+Assumptions!$B$9*(1-Assumptions!$B$10))+B8*Assumptions!$B$11+B9*Assumptions!$B$12 | C42: =C5*Assumptions!$B$4+C6*(Assumptions!$B$5*Assumptions!$B$7+Assumptions!$B$6*(1-Assumptions!$B$7))+C7*(Assumptions!$B$8*Assumptions!$B$10+Assumptions!$B$9*(1-Assumptions!$B$10))+C8*Assumptions!$B$11+C9*Assumptions!$B$12 | D42: =D5*Assumptions!$B$4+D6*(Assumptions!$B$5*Assumptions!$B$7+Assumptions!$B$6*(1-Assumptions!$B$7))+D7*(Assumptions!$B$8*Assumptions!$B$10+Assumptions!$B$9*(1-Assumptions!$B$10))+D8*Assumptions!$B$11+D9*Assumptions!$B$12
A43: (recognised revenue above; bookings = total value signed, incl. future years)

Sheet Unit Economics
A1: UNIT ECONOMICS — per intro buyer (Base assumptions, RM)
A3: Probability of reaching each rung
A4: Intro | B4: 1
A5: Bootcamp | B5: =Assumptions!$B$15*Assumptions!$F$42
A6: Certificate | B6: =B5*Assumptions!$B$16*Assumptions!$F$42
A7: Diploma | B7: =B6*Assumptions!$B$17*Assumptions!$F$42
A8: Mastery | B8: =B7*Assumptions!$B$18*Assumptions!$F$42
A10: Revenue value per intro buyer (full price × probability)
A11: Intro | B11: =B4*Assumptions!$B$4
A12: Bootcamp | B12: =B5*(Assumptions!$B$5*Assumptions!$B$7+Assumptions!$B$6*(1-Assumptions!$B$7))
A13: Certificate | B13: =B6*(Assumptions!$B$8*Assumptions!$B$10+Assumptions!$B$9*(1-Assumptions!$B$10))
A14: Diploma | B14: =B7*Assumptions!$B$11
A15: Mastery | B15: =B8*Assumptions!$B$12
A16: Course LTV / intro buyer | B16: =SUM(B11:B15)
A17: Tool LTV / intro buyer | B17: =B5*Assumptions!$F$44*Assumptions!$B$13*Assumptions!$B$21
A18: TOTAL revenue LTV / intro buyer | B18: =B16+B17
A20: Contribution & returns
A21: Course contribution / intro | B21: =B16*(1-Assumptions!$B$27)
A22: Tool contribution / intro | B22: =B17*Assumptions!$B$22
A23: TOTAL contribution LTV / intro | B23: =B21+B22
A24: CAC per intro (Base) | B24: =Assumptions!$F$45
A25: LTV : CAC (contribution) | B25: =B23/B24
A26: LTV : CAC (revenue) | B26: =B18/B24
A27: First sale covers CAC? (intro − CAC) | B27: =Assumptions!$B$4-B24
A29: Break-even (Year-1 basis, base margins, volume the only variable)
A30: Fixed OpEx / yr | B30: =Assumptions!$B$28+Assumptions!$B$29+Assumptions!$B$30+Assumptions!$B$31+Assumptions!$B$32
A31: Film gross profit (base, offsets fixed) | B31: ='P&L (Year 1)'!C19*Assumptions!$B$25
A32: Course+Tool GP per intro (base) | B32: =('P&L (Year 1)'!C17*(1-Assumptions!$B$27)+'P&L (Year 1)'!C18*Assumptions!$B$22)/'P&L (Year 1)'!C5
A33: Break-even intro buyers / yr | B33: =(B30-B31)/(B32-Assumptions!$F$45)

Sheet Cash Flow (monthly)
A1: MONTHLY CASH FLOW — Year 1, Base scenario (RM)
A2: Long programs modelled as monthly installments (worst case for cash). Blue=input, yellow=key lever.
B4: M1 | C4: M2 | D4: M3 | E4: M4 | F4: M5 | G4: M6 | H4: M7 | I4: M8 | J4: M9 | K4: M10 | L4: M11 | M4: M12 | N4: Year 1
A5: VOLUMES (students)
A6: Intro buyers (input ramp) | B6: 50 | C6: 80 | D6: 120 | E6: 150 | F6: 170 | G6: 190 | H6: 200 | I6: 210 | J6: 210 | K6: 210 | L6: 200 | M6: 210 | N6: =SUM(B6:M6)
A7: Bootcamp (25% of prior-month intro) | B7: 0 | C7: =B6*Assumptions!$B$15 | D7: =C6*Assumptions!$B$15 | E7: =D6*Assumptions!$B$15 | F7: =E6*Assumptions!$B$15 | G7: =F6*Assumptions!$B$15 | H7: =G6*Assumptions!$B$15 | I7: =H6*Assumptions!$B$15 | J7: =I6*Assumptions!$B$15 | ... M7: =L6*Assumptions!$B$15 | N7: =SUM(B7:M7)
A8: Certificate enrol (20% of prior boot) | B8: 0 | C8: =B7*Assumptions!$B$16 | D8: =C7*Assumptions!$B$16 | E8: =D7*Assumptions!$B$16 | F8: =E7*Assumptions!$B$16 | G8: =F7*Assumptions!$B$16 | H8: =G7*Assumptions!$B$16 | I8: =H7*Assumptions!$B$16 | J8: =I7*Assumptions!$B$16 | ... M8: =L7*Assumptions!$B$16 | N8: =SUM(B8:M8)
A9: Diploma enrol (35% of prior cert) | B9: 0 | C9: =B8*Assumptions!$B$17 | D9: =C8*Assumptions!$B$17 | E9: =D8*Assumptions!$B$17 | F9: =E8*Assumptions!$B$17 | G9: =F8*Assumptions!$B$17 | H9: =G8*Assumptions!$B$17 | I9: =H8*Assumptions!$B$17 | J9: =I8*Assumptions!$B$17 | ... M9: =L8*Assumptions!$B$17 | N9: =SUM(B9:M9)
A10: Mastery enrol (35% of prior dip) | B10: 0 | C10: =B9*Assumptions!$B$18 | D10: =C9*Assumptions!$B$18 | E10: =D9*Assumptions!$B$18 | F10: =E9*Assumptions!$B$18 | G10: =F9*Assumptions!$B$18 | H10: =G9*Assumptions!$B$18 | I10: =H9*Assumptions!$B$18 | J10: =I9*Assumptions!$B$18 | ... M10: =L9*Assumptions!$B$18 | N10: =SUM(B10:M10)
A11: CUMULATIVE (active for recurring cash)
A12: Cum bootcamp | B12: =B7 | C12: =B12+C7 | D12: =C12+D7 | E12: =D12+E7 | F12: =E12+F7 | G12: =F12+G7 | H12: =G12+H7 | I12: =H12+I7 | J12: =I12+J7 | ... M12: =L12+M7 | N12: =M12
A13: Cum certificate | B13: =B8 | C13: =B13+C8 | D13: =C13+D8 | E13: =D13+E8 | F13: =E13+F8 | G13: =F13+G8 | H13: =G13+H8 | I13: =H13+I8 | J13: =I13+J8 | ... M13: =L13+M8 | N13: =M13
A14: Cum diploma | B14: =B9 | C14: =B14+C9 | D14: =C14+D9 | E14: =D14+E9 | F14: =E14+F9 | G14: =F14+G9 | H14: =G14+H9 | I14: =H14+I9 | J14: =I14+J9 | ... M14: =L14+M9 | N14: =M14
A15: Cum mastery | B15: =B10 | C15: =B15+C10 | D15: =C15+D10 | E15: =D15+E10 | F15: =E15+F10 | G15: =F15+G10 | H15: =G15+H10 | I15: =H15+I10 | J15: =I15+J10 | ... M15: =L15+M10 | N15: =M15
A16: Tool paying subs (cum boot lag-3 × paid%) | B16: 0 | C16: 0 | D16: 0 | E16: =B12*Assumptions!$F$44 | F16: =C12*Assumptions!$F$44 | G16: =D12*Assumptions!$F$44 | H16: =E12*Assumptions!$F$44 | I16: =F12*Assumptions!$F$44 | J16: =G12*Assumptions!$F$44 | K16: =H12*Assumptions!$F$44 | L16: =I12*Assumptions!$F$44 | M16: =J12*Assumptions!$F$44 | N16: =M16
A18: CASH IN
A19: Intro (on purchase) | B19: =B6*Assumptions!$B$4 | C19: =C6*Assumptions!$B$4 | D19: =D6*Assumptions!$B$4 | E19: =E6*Assumptions!$B$4 | F19: =F6*Assumptions!$B$4 | G19: =G6*Assumptions!$B$4 | H19: =H6*Assumptions!$B$4 | I19: =I6*Assumptions!$B$4 | ... M19: =M6*Assumptions!$B$4 | N19: =SUM(B19:M19)
A20: Bootcamp (upfront) | B20: =B7*(Assumptions!$B$5*Assumptions!$B$7+Assumptions!$B$6*(1-Assumptions!$B$7)) | C20: =C7*(Assumptions!$B$5*Assumptions!$B$7+Assumptions!$B$6*(1-Assumptions!$B$7)) | D20: =D7*(Assumptions!$B$5*Assumptions!$B$7+Assumptions!$B$6*(1-Assumptions!$B$7)) | E20: =E7*(Assumptions!$B$5*Assumptions!$B$7+Assumptions!$B$6*(1-Assumptions!$B$7)) | F20: =F7*(Assumptions!$B$5*Assumptions!$B$7+Assumptions!$B$6*(1-Assumptions!$B$7)) | G20: =G7*(Assumptions!$B$5*Assumptions!$B$7+Assumptions!$B$6*(1-Assumptions!$B$7)) | H20: =H7*(Assumptions!$B$5*Assumptions!$B$7+Assumptions!$B$6*(1-Assumptions!$B$7)) | I20: =I7*(Assumptions!$B$5*Assumptions!$B$7+Assumptions!$B$6*(1-Assumptions!$B$7)) | ... M20: =M7*(Assumptions!$B$5*Assumptions!$B$7+Assumptions!$B$6*(1-Assumptions!$B$7)) | N20: =SUM(B20:M20)
A21: Certificate (monthly installment) | B21: =B13*((Assumptions!$B$8*Assumptions!$B$10+Assumptions!$B$9*(1-Assumptions!$B$10))/12) | C21: =C13*((Assumptions!$B$8*Assumptions!$B$10+Assumptions!$B$9*(1-Assumptions!$B$10))/12) | D21: =D13*((Assumptions!$B$8*Assumptions!$B$10+Assumptions!$B$9*(1-Assumptions!$B$10))/12) | E21: =E13*((Assumptions!$B$8*Assumptions!$B$10+Assumptions!$B$9*(1-Assumptions!$B$10))/12) | F21: =F13*((Assumptions!$B$8*Assumptions!$B$10+Assumptions!$B$9*(1-Assumptions!$B$10))/12) | G21: =G13*((Assumptions!$B$8*Assumptions!$B$10+Assumptions!$B$9*(1-Assumptions!$B$10))/12) | H21: =H13*((Assumptions!$B$8*Assumptions!$B$10+Assumptions!$B$9*(1-Assumptions!$B$10))/12) | I21: =I13*((Assumptions!$B$8*Assumptions!$B$10+Assumptions!$B$9*(1-Assumptions!$B$10))/12) | ... M21: =M13*((Assumptions!$B$8*Assumptions!$B$10+Assumptions!$B$9*(1-Assumptions!$B$10))/12) | N21: =SUM(B21:M21)
A22: Diploma (monthly installment) | B22: =B14*(Assumptions!$B$11/24) | C22: =C14*(Assumptions!$B$11/24) | D22: =D14*(Assumptions!$B$11/24) | E22: =E14*(Assumptions!$B$11/24) | F22: =F14*(Assumptions!$B$11/24) | G22: =G14*(Assumptions!$B$11/24) | H22: =H14*(Assumptions!$B$11/24) | I22: =I14*(Assumptions!$B$11/24) | ... M22: =M14*(Assumptions!$B$11/24) | N22: =SUM(B22:M22)
A23: Mastery (monthly, net of studio pay) | B23: =B15*(Assumptions!$B$12/48) | C23: =C15*(Assumptions!$B$12/48) | D23: =D15*(Assumptions!$B$12/48) | E23: =E15*(Assumptions!$B$12/48) | F23: =F15*(Assumptions!$B$12/48) | G23: =G15*(Assumptions!$B$12/48) | H23: =H15*(Assumptions!$B$12/48) | I23: =I15*(Assumptions!$B$12/48) | ... M23: =M15*(Assumptions!$B$12/48) | N23: =SUM(B23:M23)
A24: Tool (recurring) | B24: =B16*Assumptions!$B$13 | C24: =C16*Assumptions!$B$13 | D24: =D16*Assumptions!$B$13 | E24: =E16*Assumptions!$B$13 | F24: =F16*Assumptions!$B$13 | G24: =G16*Assumptions!$B$13 | H24: =H16*Assumptions!$B$13 | I24: =I16*Assumptions!$B$13 | ... M24: =M16*Assumptions!$B$13 | N24: =SUM(B24:M24)
A25: Films delivered (input #) | B25: 0 | C25: 0 | D25: 0 | E25: 0 | F25: 0 | G25: 1 | H25: 0 | I25: 1 | J25: 1 | K25: 2 | L25: 1 | M25: 2 | N25: =SUM(B25:M25)
A26: Film cash (on delivery) | B26: =B25*Assumptions!$B$24 | C26: =C25*Assumptions!$B$24 | D26: =D25*Assumptions!$B$24 | E26: =E25*Assumptions!$B$24 | F26: =F25*Assumptions!$B$24 | G26: =G25*Assumptions!$B$24 | H26: =H25*Assumptions!$B$24 | I26: =I25*Assumptions!$B$24 | ... M26: =M25*Assumptions!$B$24 | N26: =SUM(B26:M26)
A27: TOTAL CASH IN | B27: =B19+B20+B21+B22+B23+B24+B26 | C27: =C19+C20+C21+C22+C23+C24+C26 | D27: =D19+D20+D21+D22+D23+D24+D26 | E27: =E19+E20+E21+E22+E23+E24+E26 | F27: =F19+F20+F21+F22+F23+F24+F26 | G27: =G19+G20+G21+G22+G23+G24+G26 | H27: =H19+H20+H21+H22+H23+H24+H26 | I27: =I19+I20+I21+I22+I23+I24+I26 | ... M27: =M19+M20+M21+M22+M23+M24+M26 | N27: =SUM(B27:M27)
A29: CASH OUT
A30: Marketing (CAC × intro) | B30: =B6*Assumptions!$F$45 | C30: =C6*Assumptions!$F$45 | D30: =D6*Assumptions!$F$45 | E30: =E6*Assumptions!$F$45 | F30: =F6*Assumptions!$F$45 | G30: =G6*Assumptions!$F$45 | H30: =H6*Assumptions!$F$45 | I30: =I6*Assumptions!$F$45 | ... M30: =M6*Assumptions!$F$45 | N30: =SUM(B30:M30)
A31: Course delivery COGS | B31: =(B19+B20+B21+B22+B23)*Assumptions!$B$27 | C31: =(C19+C20+C21+C22+C23)*Assumptions!$B$27 | D31: =(D19+D20+D21+D22+D23)*Assumptions!$B$27 | E31: =(E19+E20+E21+E22+E23)*Assumptions!$B$27 | F31: =(F19+F20+F21+F22+F23)*Assumptions!$B$27 | G31: =(G19+G20+G21+G22+G23)*Assumptions!$B$27 | H31: =(H19+H20+H21+H22+H23)*Assumptions!$B$27 | I31: =(I19+I20+I21+I22+I23)*Assumptions!$B$27 | ... M31: =(M19+M20+M21+M22+M23)*Assumptions!$B$27 | N31: =SUM(B31:M31)
A32: Tool COGS | B32: =B24*(1-Assumptions!$B$22) | C32: =C24*(1-Assumptions!$B$22) | D32: =D24*(1-Assumptions!$B$22) | E32: =E24*(1-Assumptions!$B$22) | F32: =F24*(1-Assumptions!$B$22) | G32: =G24*(1-Assumptions!$B$22) | H32: =H24*(1-Assumptions!$B$22) | I32: =I24*(1-Assumptions!$B$22) | ... M32: =M24*(1-Assumptions!$B$22) | N32: =SUM(B32:M32)
A33: Film COGS | B33: =B26*(1-Assumptions!$B$25) | C33: =C26*(1-Assumptions!$B$25) | D33: =D26*(1-Assumptions!$B$25) | E33: =E26*(1-Assumptions!$B$25) | F33: =F26*(1-Assumptions!$B$25) | G33: =G26*(1-Assumptions!$B$25) | H33: =H26*(1-Assumptions!$B$25) | I33: =I26*(1-Assumptions!$B$25) | ... M33: =M26*(1-Assumptions!$B$25) | N33: =SUM(B33:M33)
A34: Fixed OpEx (team+sw+legal+G&A+brand)/12 | B34: =(Assumptions!$B$28+Assumptions!$B$29+Assumptions!$B$30+Assumptions!$B$31+Assumptions!$B$32)/12 | C34: =(Assumptions!$B$28+Assumptions!$B$29+Assumptions!$B$30+Assumptions!$B$31+Assumptions!$B$32)/12 | D34: =(Assumptions!$B$28+Assumptions!$B$29+Assumptions!$B$30+Assumptions!$B$31+Assumptions!$B$32)/12 | E34: =(Assumptions!$B$28+Assumptions!$B$29+Assumptions!$B$30+Assumptions!$B$31+Assumptions!$B$32)/12 | F34: =(Assumptions!$B$28+Assumptions!$B$29+Assumptions!$B$30+Assumptions!$B$31+Assumptions!$B$32)/12 | G34: =(Assumptions!$B$28+Assumptions!$B$29+Assumptions!$B$30+Assumptions!$B$31+Assumptions!$B$32)/12 | H34: =(Assumptions!$B$28+Assumptions!$B$29+Assumptions!$B$30+Assumptions!$B$31+Assumptions!$B$32)/12 | I34: =(Assumptions!$B$28+Assumptions!$B$29+Assumptions!$B$30+Assumptions!$B$31+Assumptions!$B$32)/12 | ... M34: =(Assumptions!$B$28+Assumptions!$B$29+Assumptions!$B$30+Assumptions!$B$31+Assumptions!$B$32)/12 | N34: =SUM(B34:M34)
A35: TOTAL CASH OUT | B35: =B30+B31+B32+B33+B34 | C35: =C30+C31+C32+C33+C34 | D35: =D30+D31+D32+D33+D34 | E35: =E30+E31+E32+E33+E34 | F35: =F30+F31+F32+F33+F34 | G35: =G30+G31+G32+G33+G34 | H35: =H30+H31+H32+H33+H34 | I35: =I30+I31+I32+I33+I34 | ... M35: =M30+M31+M32+M33+M34 | N35: =SUM(B35:M35)
A37: NET
A38: Net cash flow | B38: =B27-B35 | C38: =C27-C35 | D38: =D27-D35 | E38: =E27-E35 | F38: =F27-F35 | G38: =G27-G35 | H38: =H27-H35 | I38: =I27-I35 | ... M38: =M27-M35 | N38: =SUM(B38:M38)
A39: Cumulative cash | B39: =B38 | C39: =B39+C38 | D39: =C39+D38 | E39: =D39+E38 | F39: =E39+F38 | G39: =F39+G38 | H39: =G39+H38 | I39: =H39+I38 | J39: =I39+J38 | ... M39: =L39+M38 | N39: =M39
A41: Peak funding need (lowest cumulative cash) | B41: =MIN(B39:M39)
A42: Ending cash (Month 12) | B42: =M39
A43: Month turns cash-flow positive (net>0)
A44: NOTE: If Diploma/Mastery use 3rd-party financing (paid upfront) instead of monthly, cash-in is earlier and the trough shrinks. Change the installment rows to model that.

Sheet 3-Year Projection
A1: 3-YEAR PROJECTION (annualised cohort basis, RM)
A2: Long-program fees annualised over duration; cohorts overlap across years. Blue=input, yellow=lever. NOTE: Year 1 here uses an annualised method, so it reads higher than the deliberately-conservative 'P&L (Year 1)' tab.
A4: Line item (RM) | B4: Year 1 | C4: Year 2 | D4: Year 3
A5: INPUTS (edit these)
A6: Intro buyers / year | B6: 2000 | C6: 5000 | D6: 10000
A7: CAC per intro (RM) | B7: 150 | C7: 130 | D7: 110
A8: Films delivered / year | B8: 8 | C8: 20 | D8: 40
A9: Team salaries / year | B9: 720000 | C9: 1400000 | D9: 2400000
A10: Software / platform / year | B10: 120000 | C10: 200000 | D10: 320000
A11: Legal / compliance / year | B11: 80000 | C11: 120000 | D11: 180000
A12: G&A / year | B12: 100000 | C12: 200000 | D12: 350000
A13: Brand marketing / year | B13: 100000 | C13: 250000 | D13: 500000
A14: Tool annual retention % | B14: 0.54 | C14: 0.54 | D14: 0.54
A16: VOLUMES (new enrolments unless noted)
A17: Bootcamp | B17: =B6*Assumptions!$B$15 | C17: =C6*Assumptions!$B$15 | D17: =D6*Assumptions!$B$15
A18: Certificate (new) | B18: =B17*Assumptions!$B$16 | C18: =C17*Assumptions!$B$16 | D18: =D17*Assumptions!$B$16
A19: Diploma (new) | B19: =B18*Assumptions!$B$17 | C19: =C18*Assumptions!$B$17 | D19: =D18*Assumptions!$B$17
A20: Mastery (new) | B20: =B19*Assumptions!$B$18 | C20: =C19*Assumptions!$B$18 | D20: =D19*Assumptions!$B$18
A21: Diploma ACTIVE (2-yr overlap) | B21: =B19 | C21: =C19+B19 | D21: =D19+C19
A22: Mastery ACTIVE (multi-yr overlap) | B22: =B20 | C22: =C20+B20 | D22: =D20+C20+B20
A23: Tool new paying subs (boot × paid%) | B23: =B17*Assumptions!$F$44 | C23: =C17*Assumptions!$F$44 | D23: =D17*Assumptions!$F$44
A24: Tool ACTIVE subs (retained + new) | B24: =B23 | C24: =B24*C14+C23 | D24: =C24*D14+D23
A26: REVENUE (annualised)
A27: Intro | B27: =B6*Assumptions!$B$4 | C27: =C6*Assumptions!$B$4 | D27: =D6*Assumptions!$B$4
A28: Bootcamp | B28: =B17*(Assumptions!$B$5*Assumptions!$B$7+Assumptions!$B$6*(1-Assumptions!$B$7)) | C28: =C17*(Assumptions!$B$5*Assumptions!$B$7+Assumptions!$B$6*(1-Assumptions!$B$7)) | D28: =D17*(Assumptions!$B$5*Assumptions!$B$7+Assumptions!$B$6*(1-Assumptions!$B$7))
A29: Certificate (1-yr, full) | B29: =B18*(Assumptions!$B$8*Assumptions!$B$10+Assumptions!$B$9*(1-Assumptions!$B$10)) | C29: =C18*(Assumptions!$B$8*Assumptions!$B$10+Assumptions!$B$9*(1-Assumptions!$B$10)) | D29: =D18*(Assumptions!$B$8*Assumptions!$B$10+Assumptions!$B$9*(1-Assumptions!$B$10))
A30: Diploma (active × RM/yr) | B30: =B21*(Assumptions!$B$11/2) | C30: =C21*(Assumptions!$B$11/2) | D30: =D21*(Assumptions!$B$11/2)
A31: Mastery (active × RM/yr) | B31: =B22*(Assumptions!$B$12/4) | C31: =C22*(Assumptions!$B$12/4) | D31: =D22*(Assumptions!$B$12/4)
A32: Course revenue | B32: =SUM(B27:B31) | C32: =SUM(C27:C31) | D32: =SUM(D27:D31)
A33: Tool revenue (active × RM/mo × 12) | B33: =B24*Assumptions!$B$13*12 | C33: =C24*Assumptions!$B$13*12 | D33: =D24*Assumptions!$B$13*12
A34: Film revenue (DFY) | B34: =B8*Assumptions!$B$24 | C34: =C8*Assumptions!$B$24 | D34: =D8*Assumptions!$B$24
A35: TOTAL REVENUE | B35: =B32+B33+B34 | C35: =C32+C33+C34 | D35: =D32+D33+D34
A37: COST OF DELIVERY
A38: Course COGS | B38: =B32*Assumptions!$B$27 | C38: =C32*Assumptions!$B$27 | D38: =D32*Assumptions!$B$27
A39: Tool COGS | B39: =B33*(1-Assumptions!$B$22) | C39: =C33*(1-Assumptions!$B$22) | D39: =D33*(1-Assumptions!$B$22)
A40: Film COGS | B40: =B34*(1-Assumptions!$B$25) | C40: =C34*(1-Assumptions!$B$25) | D40: =D34*(1-Assumptions!$B$25)
A41: Total COGS | B41: =SUM(B38:B40) | C41: =SUM(C38:C40) | D41: =SUM(D38:D40)
A42: GROSS PROFIT | B42: =B35-B41 | C42: =C35-C41 | D42: =D35-D41
A43: Gross margin % | B43: =B42/B35 | C43: =C42/C35 | D43: =D42/D35
A45: OPERATING EXPENSES
...
